00:50:37 | Ждать придется: 10
| 00:50:40 | Перехожу по ссылке
Traceback (most recent call last):
  File "bot_V2.py", line 119, in <module>
    fp = urllib.request.urlopen(url_rec)
  File "/usr/lib/python3.8/urllib/request.py", line 222, in urlopen
    return opener.open(url, data, timeout)
  File "/usr/lib/python3.8/urllib/request.py", line 531, in open
    response = meth(req, response)
  File "/usr/lib/python3.8/urllib/request.py", line 640, in http_response
    response = self.parent.error(
  File "/usr/lib/python3.8/urllib/request.py", line 563, in error
    result = self._call_chain(*args)
  File "/usr/lib/python3.8/urllib/request.py", line 502, in _call_chain
    result = func(*args)
  File "/usr/lib/python3.8/urllib/request.py", line 755, in http_error_302
    return self.parent.open(new, timeout=req.timeout)
  File "/usr/lib/python3.8/urllib/request.py", line 531, in open
    response = meth(req, response)
  File "/usr/lib/python3.8/urllib/request.py", line 640, in http_response
    response = self.parent.error(
  File "/usr/lib/python3.8/urllib/request.py", line 563, in error
    result = self._call_chain(*args)
  File "/usr/lib/python3.8/urllib/request.py", line 502, in _call_chain
    result = func(*args)
  File "/usr/lib/python3.8/urllib/request.py", line 755, in http_error_302
    return self.parent.open(new, timeout=req.timeout)
  File "/usr/lib/python3.8/urllib/request.py", line 531, in open
    response = meth(req, response)
  File "/usr/lib/python3.8/urllib/request.py", line 640, in http_response
    response = self.parent.error(
  File "/usr/lib/python3.8/urllib/request.py", line 569, in error
    return self._call_chain(*args)
  File "/usr/lib/python3.8/urllib/request.py", line 502, in _call_chain
    result = func(*args)
  File "/usr/lib/python3.8/urllib/request.py", line 649, in http_error_default
    raise HTTPError(req.full_url, code, msg, hdrs, fp)
urllib.error.HTTPError: HTTP Error 403: Forbidden
